<mujoco model="mpc-ball-balancing-plate">
    <compiler autolimits="true"/>
    <option timestep="0.0001" iterations="50" solver="PGS" gravity="0 0 -9.81"/>
  
    <asset>
      <texture name="grid" type="2d" builtin="checker" rgb1=".1 .2 .3"
       rgb2=".2 .3 .4" width="300" height="300"/>
      <material name="grid" texture="grid" texrepeat="8 8" reflectance=".2"/>
    </asset>
  
    <worldbody>
      <geom size=".2 .2 .01" type="plane" material="grid"/>
      <light pos="0 0 .6"/>
      <camera name="closeup" pos="0 -.1 .07" xyaxes="1 0 0 0 1 2"/>

      <!-- <body name="ball" pos="0 0 0.1">
        <joint name="joint_ball" type="free"/>
        <geom name="shape_ball" type="sphere" size=".01" rgba="0.7 0.7 0.7 1" condim="3"/>
        <inertial pos="0 0 0" mass="0.01" fullinertia="0.01 0.01 0.01 -0.001 -0.001 -0.001"/>
      </body> -->

      <body name="base_link" pos="0 0 0">
        <geom name="stem" type="cylinder" pos="0 0 0.035" size="0.005 .035" rgba="0.7 0.7 0.7 1"/>
        <body name="pivot" pos="0 0 0.0725">
          <geom name="shape_pivot" type="sphere" size=".0025" pos="0 0 0" rgba="0.5 0.5 0.5 1"/>
          <body name="plate" pos="0 0 0.005">
            <joint name="joint_plate" type="ball" pos="0 0 0"/>
            <geom name="shape_plate" type="box" size="0.1 0.1 0.001" rgba="0.7 0.7 0.7 1" condim="3"/>
            <inertial pos="0 0 0" mass="0.01" fullinertia="0.001 0.001 0.001 1e-4 1e-4 1e-4"/>

            <site name="joint_plate_x1" pos="-0.1 0 0" rgba="1 0 0 1"/>
            <site name="joint_plate_x2" pos="0.1 0 0" rgba="1 1 0 1"/>
            <site name="joint_plate_y1" pos="0 -0.1 0" rgba="0 1 0 1"/>
            <site name="joint_plate_y2" pos="0 0.1 0" rgba="0 0 1 1"/>

          </body>
        </body>
      </body>
    </worldbody>
  
    <actuator>
      <motor name="motor_plate_x1" site="joint_plate_x1" gear="0 0 1 0 0 0"/>
      <motor name="motor_plate_x2" site="joint_plate_x2" gear="0 0 1 0 0 0"/>
      <motor name="motor_plate_y1" site="joint_plate_y1" gear="0 0 1 0 0 0"/>
      <motor name="motor_plate_y2" site="joint_plate_y2" gear="0 0 1 0 0 0"/>
    </actuator>

  </mujoco>